Workbook
Name Discipline: '[1]Discipline Codes'!$A$5:$A$21
Name Discipline: 'Discipline Codes'!$A$5:$A$23
Name DISCPPE: '[1]Discipline Codes'!$D$5:$D$14
Name DISCPPE: 'Discipline Codes'!#REF!
Name Month: [1]Dropdown!$A$2:$A$13
Name Month: #REF!
Name mylist: #REF!
Name Patterns: '[2]List Fields'!$B$2:$B$108
Name Patterns: #REF!
Name Phase: [1]Dropdown!$D$2:$D$6
Name Phase: #REF!
Name PNO: [1]Dropdown!$F$2:$F$4
Name PNO: #REF!
Name PPE: [1]Dropdown!$B$2:$B$3
Name PPE: #REF!
Name Project: [1]Dropdown!$E$2:$E$3
Name Project: #REF!
Name Quote: [1]Dropdown!$C$2:$C$3
Name Quote: #REF!
Name Rev: [1]Revision!$H$2:$H$12
Name Rev: #REF!
Name Type: '[1]Document and Drawing Type'!$A$8:$A$118
Name Type: 'Document and Drawing Type'!$A$5:$A$29
Name WBS: 'PPE WBS Codes'!$E$2:$E$31
Name WBS: #REF!
Name WBSD: 'PPE WBS Codes'!$F$2:$F$31
Name WBSD: #REF!

Sheet Tracker
A1: Area/ WBS No. | B1: Discipline | C1: RDMC Document Number | D1: Sum of % Complete
A2: 6200 | D2: 0
A3: 6240 | D3: 0
A4: 6243 | D4: 0
A5: 6250 | D5: 0
A6: 6260 | D6: 0
A7: 6262 | D7: 0
A8: 6263 | D8: 0
A9: 6264 | D9: 0
A10: 6280 | D10: 0
A11: 6286 | D11: 0
A12: 6292 | D12: 0
A13: 0000 | D13: 0
A14: 0100 | D14: 0
A15: Grand Total | D15: 0

Sheet Docs not in Use
A1: Project Number | B1: Package Number | C1: Area/ WBS No. | D1: Discipline | E1: Document Type | F1: Sequential Number | G1: Revision | H1: RDMC Document Number | I1: PPE Doc Number | J1: Sht. # of # | K1: Area / Facility | L1: Major Description | M1: Broad Type | N1: Full Title | O1: Rev A Transmittal Date | P1: Rev 0 Transmittal Date | Q1: Aconex Doc Status | R1: Aconex Review Status | S1: % Complete | T1: Doc Owner | U1: Comments | V1: Due Date | W1: Main Group | X1: Sub Group | Y1: BH | Z1: Drawing Pack
A2: 6105A | B2: K124 | C2: 0000 | D2: B | E2: REQ | F2: 0001 | G2: A | H2: =A2&B2&"-"&C2&"-"&D2&E2&"-"&F2 -> 6105AK124-0000-BREQ-0001 | I2: ="Q24050972"&"-"&"09"&"-"&C2&"-"&D2&"-"&E2&"-"&F2 -> Q24050972-09-0000-B-REQ-0001 | K2: General | L2: Change Order Request | M2: General | N2: =K2&" - "&L2&" - "&M2 -> General - Change Order Request - General | Q2: No status | R2: No status | T2: MK | U2: COR'S | W2: N/A | X2: N/A | Y2: N/A | Z2: N/A
A3: 6105A | B3: K124 | C3: 0000 | D3: G | E3: PRC | F3: 0001 | G3: A | H3: =A3&B3&"-"&C3&"-"&D3&E3&"-"&F3 -> 6105AK124-0000-GPRC-0001 | I3: ="Q24050972"&"-"&"09"&"-"&C3&"-"&D3&"-"&E3&"-"&F3 -> Q24050972-09-0000-G-PRC-0001 | K3: General | L3: PPE Commissioning SharePoint Document Transmittal Procedure | M3: General | N3: =K3&" - "&L3&" - "&M3 -> General - PPE Commissioning SharePoint Document Transmittal Procedure - General | Q3: No status | R3: No status | T3: CP | W3: N/A | X3: N/A | Y3: N/A | Z3: N/A
A4: 6105A | B4: K124 | C4: 0000 | D4: G | E4: PRC | F4: 0002 | G4: A | H4: =A4&B4&"-"&C4&"-"&D4&E4&"-"&F4 -> 6105AK124-0000-GPRC-0002 | I4: ="Q24050972"&"-"&"09"&"-"&C4&"-"&D4&"-"&E4&"-"&F4 -> Q24050972-09-0000-G-PRC-0002 | K4: General | L4: Internal Document Review Procedure | M4: General | N4: =K4&" - "&L4&" - "&M4 -> General - Internal Document Review Procedure - General | Q4: No status | R4: No status | T4: CP | W4: N/A | X4: N/A | Y4: N/A | Z4: N/A
A5: 6105A | B5: K124 | C5: 0000 | D5: G | E5: PRC | F5: 0003 | G5: A | H5: =A5&B5&"-"&C5&"-"&D5&E5&"-"&F5 -> 6105AK124-0000-GPRC-0003 | I5: ="Q24050972"&"-"&"10"&"-"&C5&"-"&D5&"-"&E5&"-"&F5 -> Q24050972-10-0000-G-PRC-0003 | K5: General | L5: PPE Vendor SharePoint Procedure | M5: General | N5: =K5&" - "&L5&" - "&M5 -> General - PPE Vendor SharePoint Procedure - General | Q5: No status | R5: No status | T5: CP | W5: N/A | X5: N/A | Y5: N/A | Z5: N/A
A6: 6105A | B6: K124 | C6: 0000 | D6: G | E6: PRC | F6: 0004 | G6: A | H6: =A6&B6&"-"&C6&"-"&D6&E6&"-"&F6 -> 6105AK124-0000-GPRC-0004 | I6: ="Q24050972"&"-"&"01"&"-"&C6&"-"&D6&"-"&E6&"-"&F6 -> Q24050972-01-0000-G-PRC-0004 | K6: General | L6: PPE Formal App Review Procedure | M6: General | N6: =K6&" - "&L6&" - "&M6 -> General - PPE Formal App Review Procedure - General | Q6: No status | R6: No status | T6: CP | W6: N/A | X6: N/A | Y6: N/A | Z6: N/A

Sheet CDDL
A1: Project Number | B1: Package Number | C1: Area/ WBS No. | D1: Discipline | E1: Document Type | F1: Sequential Number | G1: Revision | H1: RDMC Document Number | I1: PPE Doc Number | J1: Sht. # of # | K1: Area / Facility | L1: Major Description | M1: Broad Type | N1: Full Title | O1: Rev A Transmittal Date | P1: Rev 0 Transmittal Date | Q1: Aconex Doc Status | R1: Aconex Review Status | S1: % Complete | T1: Doc Owner | U1: Comments | V1: Due Date | W1: Main Group | X1: Sub Group | Y1: BH | Z1: Drawing Pack | AA1: Activity ID | AB1: Schedule Status
A2: 6105A | B2: K124 | C2: 6200 | D2: E | E2: BOM | F2: 0001 | G2: A | H2: =A2&B2&"-"&C2&"-"&D2&E2&"-"&F2 -> 6105AK124-6200-EBOM-0001 | I2: ="Q24050972"&"-"&"07"&"-"&C2&"-"&D2&"-"&E2&"-"&F2 -> Q24050972-07-6200-E-BOM-0001 | K2: =VLOOKUP(C2,'PPE WBS Codes'!$E$3:$F$79,2,0) -> On-Site Power Supply and Transmission | L2: Neutral Earthing Compensator Resistor (33kV NECr) | M2: Bill of Material | N2: =K2&" - "&L2&" - "&M2 -> On-Site Power Supply and Transmission - Neutral Earthing Compensator Resistor (33kV NECr) - Bill of Material | Q2: =IFERROR(VLOOKUP(PPE_PH1_CDDL[[#This Row],[RDMC Document Number]],[3]Docs!$B:$F,4,0),"No Placeholder Yet") -> RES - Reserved Placeholder | R2: =IFERROR(VLOOKUP(PPE_PH1_CDDL[[#This Row],[RDMC Document Number]],[3]Docs!$B:$F,5,0),"No Placeholder Yet") -> Pending | S2: =IF(AND(O2<>"",P2<>"",R2="Approved"),100%, IF(AND(O2<>"",P2<>""),66.67%, IF(O2<>"",33.33%, 0))) -> 0 | T2: IS | V2: TENDER | W2: Neutral Earthing Compensator Resistor (33kV NECr) | X2: Bill of Material | AB2: Pending
A3: 6105A | B3: K124 | C3: 6200 | D3: E | E3: BOM | F3: 0002 | G3: A | H3: =A3&B3&"-"&C3&"-"&D3&E3&"-"&F3 -> 6105AK124-6200-EBOM-0002 | I3: ="Q24050972"&"-"&"07"&"-"&C3&"-"&D3&"-"&E3&"-"&F3 -> Q24050972-07-6200-E-BOM-0002 | K3: =VLOOKUP(C3,'PPE WBS Codes'!$E$3:$F$79,2,0) -> On-Site Power Supply and Transmission | L3: Neutral Earthing Reactor (11kV NER) | M3: Bill of Material | N3: =K3&" - "&L3&" - "&M3 -> On-Site Power Supply and Transmission - Neutral Earthing Reactor (11kV NER) - Bill of Material | Q3: =IFERROR(VLOOKUP(PPE_PH1_CDDL[[#This Row],[RDMC Document Number]],[3]Docs!$B:$F,4,0),"No Placeholder Yet") -> RES - Reserved Placeholder | R3: =IFERROR(VLOOKUP(PPE_PH1_CDDL[[#This Row],[RDMC Document Number]],[3]Docs!$B:$F,5,0),"No Placeholder Yet") -> Pending | S3: =IF(AND(O3<>"",P3<>"",R3="Approved"),100%, IF(AND(O3<>"",P3<>""),66.67%, IF(O3<>"",33.33%, 0))) -> 0 | T3: IS | V3: TENDER | W3: Neutral Earthing Reactor (11kV NER) | X3: Bill of Material | AB3: Pending
A4: 6105A | B4: K124 | C4: 6200 | D4: E | E4: BOM | F4: 0003 | G4: A | H4: =A4&B4&"-"&C4&"-"&D4&E4&"-"&F4 -> 6105AK124-6200-EBOM-0003 | I4: ="Q24050972"&"-"&"07"&"-"&C4&"-"&D4&"-"&E4&"-"&F4 -> Q24050972-07-6200-E-BOM-0003 | K4: =VLOOKUP(C4,'PPE WBS Codes'!$E$3:$F$79,2,0) -> On-Site Power Supply and Transmission | L4: Power Transformers - 33/11kV - 25MVA | M4: Bill of Material | N4: =K4&" - "&L4&" - "&M4 -> On-Site Power Supply and Transmission - Power Transformers - 33/11kV - 25MVA - Bill of Material | Q4: =IFERROR(VLOOKUP(PPE_PH1_CDDL[[#This Row],[RDMC Document Number]],[3]Docs!$B:$F,4,0),"No Placeholder Yet") -> RES - Reserved Placeholder | R4: =IFERROR(VLOOKUP(PPE_PH1_CDDL[[#This Row],[RDMC Document Number]],[3]Docs!$B:$F,5,0),"No Placeholder Yet") -> Pending | S4: =IF(AND(O4<>"",P4<>"",R4="Approved"),100%, IF(AND(O4<>"",P4<>""),66.67%, IF(O4<>"",33.33%, 0))) -> 0 | T4: IS | V4: TENDER | W4: Power Transformers | X4: Bill of Material | AB4: Pending
A5: 6105A | B5: K124 | C5: 6263 | D5: E | E5: BOM | F5: 0001 | G5: A | H5: =A5&B5&"-"&C5&"-"&D5&E5&"-"&F5 -> 6105AK124-6263-EBOM-0001 | I5: ="Q24050972"&"-"&"07"&"-"&C5&"-"&D5&"-"&E5&"-"&F5 -> Q24050972-07-6263-E-BOM-0001 | K5: =VLOOKUP(C5,'PPE WBS Codes'!$E$3:$F$79,2,0) -> 36 MVA Power Station 1 | L5: High Speed Diesel Generators | M5: Bill of Material | N5: =K5&" - "&L5&" - "&M5 -> 36 MVA Power Station 1 - High Speed Diesel Generators - Bill of Material | Q5: =IFERROR(VLOOKUP(PPE_PH1_CDDL[[#This Row],[RDMC Document Number]],[3]Docs!$B:$F,4,0),"No Placeholder Yet") -> RES - Reserved Placeholder | R5: =IFERROR(VLOOKUP(PPE_PH1_CDDL[[#This Row],[RDMC Document Number]],[3]Docs!$B:$F,5,0),"No Placeholder Yet") -> Pending | S5: =IF(AND(O5<>"",P5<>"",R5="Approved"),100%, IF(AND(O5<>"",P5<>""),66.67%, IF(O5<>"",33.33%, 0))) -> 0 | T5: IS | V5: TENDER | W5: High Speed Diesel Generators | X5: Bill of Material | AB5: Pending
A6: 6105A | B6: K124 | C6: 6262 | D6: E | E6: BOM | F6: 0001 | G6: A | H6: =A6&B6&"-"&C6&"-"&D6&E6&"-"&F6 -> 6105AK124-6262-EBOM-0001 | I6: ="Q24050972"&"-"&"11"&"-"&C6&"-"&D6&"-"&E6&"-"&F6 -> Q24050972-11-6262-E-BOM-0001 | J6: Sht 1 of 1 | K6: =VLOOKUP(C6,'PPE WBS Codes'!$E$3:$F$79,2,0) -> Emergency Power Substation 1 and Control Room 1 | L6: 33/11kV Substation | M6: Yard Plant & Equipment - Bill of Material | N6: =K6&" - "&L6&" - "&M6&" - "&J6 -> Emergency Power Substation 1 and Control Room 1 - 33/11kV Substation - Yard Plant & Equipment - Bill of Material - Sht 1 of 1 | Q6: =IFERROR(VLOOKUP(PPE_PH1_CDDL[[#This Row],[RDMC Document Number]],[3]Docs!$B:$F,4,0),"No Placeholder Yet") -> RES - Reserved Placeholder | R6: =IFERROR(VLOOKUP(PPE_PH1_CDDL[[#This Row],[RDMC Document Number]],[3]Docs!$B:$F,5,0),"No Placeholder Yet") -> Pending | S6: =IF(AND(O6<>"",P6<>"",R6="Approved"),100%, IF(AND(O6<>"",P6<>""),66.67%, IF(O6<>"",33.33%, 0))) -> 0 | T6: IS | V6: 46157 | W6: 33/11kV Substation | X6: Bill of Material | AB6: Pending
A7: 6105A | B7: K124 | C7: 6200 | D7: B | E7: BOS | F7: 0001 | G7: A | H7: =A7&B7&"-"&C7&"-"&D7&E7&"-"&F7 -> 6105AK124-6200-BBOS-0001 | I7: ="Q24050972"&"-"&"07"&"-"&C7&"-"&D7&"-"&E7&"-"&F7 -> Q24050972-07-6200-B-BOS-0001 | K7: =VLOOKUP(C7,'PPE WBS Codes'!$E$3:$F$79,2,0) -> On-Site Power Supply and Transmission | L7: PPE EP & CM Contractual Schedule | M7: Basis of Schedule | N7: =K7&" - "&L7&" - "&M7 -> On-Site Power Supply and Transmission - PPE EP & CM Contractual Schedule - Basis of Schedule | Q7: =IFERROR(VLOOKUP(PPE_PH1_CDDL[[#This Row],[RDMC Document Number]],[3]Docs!$B:$F,4,0),"No Placeholder Yet") -> RES - Reserved Placeholder | R7: =IFERROR(VLOOKUP(PPE_PH1_CDDL[[#This Row],[RDMC Document Number]],[3]Docs!$B:$F,5,0),"No Placeholder Yet") -> Pending | S7: =IF(AND(O7<>"",P7<>"",R7="Approved"),100%, IF(AND(O7<>"",P7<>""),66.67%, IF(O7<>"",33.33%, 0))) -> 0 | T7: FO | V7: TENDER | W7: PPE EP & CM Contractual Schedule | X7: Basis of Schedule | AB7: Pending
A8: 6105A | B8: K124 | C8: 0100 | D8: G | E8: CHR | F8: 0001 | G8: A | H8: =A8&B8&"-"&C8&"-"&D8&E8&"-"&F8 -> 6105AK124-0100-GCHR-0001 | I8: ="Q24050972"&"-"&"01"&"-"&C8&"-"&D8&"-"&E8&"-"&F8 -> Q24050972-01-0100-G-CHR-0001 | K8: =VLOOKUP(C8,'PPE WBS Codes'!$E$3:$F$79,2,0) -> Project Site Wide | L8: Phase 1 Construction Management Organogram | M8: General | N8: =K8&" - "&L8&" - "&M8 -> Project Site Wide - Phase 1 Construction Management Organogram - General | Q8: =IFERROR(VLOOKUP(PPE_PH1_CDDL[[#This Row],[RDMC Document Number]],[3]Docs!$B:$F,4,0),"No Placeholder Yet") -> RES - Reserved Placeholder | R8: =IFERROR(VLOOKUP(PPE_PH1_CDDL[[#This Row],[RDMC Document Number]],[3]Docs!$B:$F,5,0),"No Placeholder Yet") -> Pending | S8: =IF(AND(O8<>"",P8<>"",R8="Approved"),100%, IF(AND(O8<>"",P8<>""),66.67%, IF(O8<>"",33.33%, 0))) -> 0 | T8: JM | V8: 46157 | W8: Organogram | X8: General | AB8: Pending
A9: 6105A | B9: K124 | C9: 6290 | D9: E | E9: DBD | F9: 0001 | G9: 0 | H9: =A9&B9&"-"&C9&"-"&D9&E9&"-"&F9 -> 6105AK124-6290-EDBD-0001 | I9: ="Q24050972"&"-"&"11"&"-"&C9&"-"&D9&"-"&E9&"-"&F9 -> Q24050972-11-6290-E-DBD-0001 | K9: =VLOOKUP(C9,'PPE WBS Codes'!$E$3:$F$79,2,0) -> Renewable Energy | L9: 150MW Solar PV Plant | M9: Basis of Design | N9: =K9&" - "&L9&" - "&M9 -> Renewable Energy - 150MW Solar PV Plant - Basis of Design | O9: 46093 | P9: 46157 | Q9: =IFERROR(VLOOKUP(PPE_PH1_CDDL[[#This Row],[RDMC Document Number]],[3]Docs!$B:$F,4,0),"No Placeholder Yet") -> IFU - Issued for Use | R9: =IFERROR(VLOOKUP(PPE_PH1_CDDL[[#This Row],[RDMC Document Number]],[3]Docs!$B:$F,5,0),"No Placeholder Yet") -> Pending | S9: =IF(AND(O9<>"",P9<>"",R9="Approved"),100%, IF(AND(O9<>"",P9<>""),66.67%, IF(O9<>"",33.33%, 0))) -> 0.6667 | T9: NL | W9: 150MW Solar PV Plant | X9: Basis of Design | AB9: Pending
A10: 6105A | B10: K124 | C10: 6290 | D10: E | E10: DBD | F10: 0002 | G10: 0 | H10: =A10&B10&"-"&C10&"-"&D10&E10&"-"&F10 -> 6105AK124-6290-EDBD-0002 | I10: ="Q24050972"&"-"&"11"&"-"&C10&"-"&D10&"-"&E10&"-"&F10 -> Q24050972-11-6290-E-DBD-0002 | K10: =VLOOKUP(C10,'PPE WBS Codes'!$E$3:$F$79,2,0) -> Renewable Energy | L10: 50MW BESS System | M10: Basis of Design | N10: =K10&" - "&L10&" - "&M10 -> Renewable Energy - 50MW BESS System - Basis of Design | O10: 46094 | P10: 46157 | Q10: =IFERROR(VLOOKUP(PPE_PH1_CDDL[[#This Row],[RDMC Document Number]],[3]Docs!$B:$F,4,0),"No Placeholder Yet") -> IFU - Issued for Use | R10: =IFERROR(VLOOKUP(PPE_PH1_CDDL[[#This Row],[RDMC Document Number]],[3]Docs!$B:$F,5,0),"No Placeholder Yet") -> Pending | S10: =IF(AND(O10<>"",P10<>"",R10="Approved"),100%, IF(AND(O10<>"",P10<>""),66.67%, IF(O10<>"",33.33%, 0))) -> 0.6667 | T10: NL | W10: 50MW BESS System | X10: Basis of Design | AB10: Pending
A11: 6105A | B11: K124 | C11: 0000 | D11: G | E11: DDR | F11: 0001 | G11: A | H11: =A11&B11&"-"&C11&"-"&D11&E11&"-"&F11 -> 6105AK124-0000-GDDR-0001 | I11: ="Q24050972"&"-"&"08"&"-"&C11&"-"&D11&"-"&E11&"-"&F11 -> Q24050972-08-0000-G-DDR-0001 | K11: General | L11: PPE Contractor Document and Data List (CDDL) | M11: CDDL | N11: =L11 -> PPE Contractor Document and Data List (CDDL) | Q11: =IFERROR(VLOOKUP(PPE_PH1_CDDL[[#This Row],[RDMC Document Number]],[3]Docs!$B:$F,4,0),"No Placeholder Yet") -> IFI - Issued for Information | R11: =IFERROR(VLOOKUP(PPE_PH1_CDDL[[#This Row],[RDMC Document Number]],[3]Docs!$B:$F,5,0),"No Placeholder Yet") -> Reviewed | S11: =IF(AND(O11<>"",P11<>"",R11="Approved"),100%, IF(AND(O11<>"",P11<>""),66.67%, IF(O11<>"",33.33%, 0))) -> 0 | T11: RV | W11: CDDL | X11: General | AB11: Pending
A12: 6105A | B12: K124 | C12: 6200 | D12: E | E12: DST | F12: 0001 | G12: A | H12: =A12&B12&"-"&C12&"-"&D12&E12&"-"&F12 -> 6105AK124-6200-EDST-0001 | I12: ="Q24050972"&"-"&"03"&"-"&C12&"-"&D12&"-"&E12&"-"&F12 -> Q24050972-03-6200-E-DST-0001 | K12: =VLOOKUP(C12,'PPE WBS Codes'!$E$3:$F$79,2,0) -> On-Site Power Supply and Transmission | L12: Primary Electrical Reticulation Network - Solar PV Switchyard, Boreholes and Camp | M12: Datasheet | N12: =K12&" - "&L12&" - "&M12 -> On-Site Power Supply and Transmission - Primary Electrical Reticulation Network - Solar PV Switchyard, Boreholes and Camp - Datasheet | Q12: =IFERROR(VLOOKUP(PPE_PH1_CDDL[[#This Row],[RDMC Document Number]],[3]Docs!$B:$F,4,0),"No Placeholder Yet") -> RES - Reserved Placeholder | R12: =IFERROR(VLOOKUP(PPE_PH1_CDDL[[#This Row],[RDMC Document Number]],[3]Docs!$B:$F,5,0),"No Placeholder Yet") -> Pending | S12: =IF(AND(O12<>"",P12<>"",R12="Approved"),100%, IF(AND(O12<>"",P12<>""),66.67%, IF(O12<>"",33.33%, 0))) -> 0 | T12: MM | V12: TENDER | W12: Primary Electrical Reticulation Network | X12: Solar PV Switchyard, Boreholes and Camp | AB12: Pending
A13: 6105A | B13: K124 | C13: 6200 | D13: E | E13: DST | F13: 0016 | G13: A | H13: =A13&B13&"-"&C13&"-"&D13&E13&"-"&F13 -> 6105AK124-6200-EDST-0016 | I13: ="Q24050972"&"-"&"07"&"-"&C13&"-"&D13&"-"&E13&"-"&F13 -> Q24050972-07-6200-E-DST-0016 | J13: Sht 1 of 1 | K13: =VLOOKUP(C13,'PPE WBS Codes'!$E$3:$F$79,2,0) -> On-Site Power Supply and Transmission | L13: Main Consumer Sub | M13: Layout | N13: =K13&" - "&L13&" - "&M13&" - "&J13 -> On-Site Power Supply and Transmission - Main Consumer Sub - Layout - Sht 1 of 1 | Q13: =IFERROR(VLOOKUP(PPE_PH1_CDDL[[#This Row],[RDMC Document Number]],[3]Docs!$B:$F,4,0),"No Placeholder Yet") -> RES - Reserved Placeholder | R13: =IFERROR(VLOOKUP(PPE_PH1_CDDL[[#This Row],[RDMC Document Number]],[3]Docs!$B:$F,5,0),"No Placeholder Yet") -> Pending | S13: =IF(AND(O13<>"",P13<>"",R13="Approved"),100%, IF(AND(O13<>"",P13<>""),66.67%, IF(O13<>"",33.33%, 0))) -> 0 | T13: CLR | V13: TENDER | W13: Main Consumer Sub | X13: Layout | AB13: Pending
A14: 6105A | B14: K124 | C14: 6243 | D14: E | E14: DST | F14: 0002 | G14: 0 | H14: =A14&B14&"-"&C14&"-"&D14&E14&"-"&F14 -> 6105AK124-6243-EDST-0002 | I14: ="Q24050972"&"-"&"06"&"-"&C14&"-"&D14&"-"&E14&"-"&F14 -> Q24050972-06-6243-E-DST-0002 | K14: =VLOOKUP(C14,'PPE WBS Codes'!$E$3:$F$79,2,0) -> 220/33 kV Plant Main Substation | L14: On-Site Power Supply & Transmission MV 33kV Main Consumer Plant Switchgear | M14: Datasheet | N14: =K14&" - "&L14&" - "&M14 -> 220/33 kV Plant Main Substation - On-Site Power Supply & Transmission MV 33kV Main Consumer Plant Switchgear - Datasheet | O14: 45957 | P14: 46093 | Q14: =IFERROR(VLOOKUP(PPE_PH1_CDDL[[#This Row],[RDMC Document Number]],[3]Docs!$B:$F,4,0),"No Placeholder Yet") -> IFU - Issued for Use | R14: =IFERROR(VLOOKUP(PPE_PH1_CDDL[[#This Row],[RDMC Document Number]],[3]Docs!$B:$F,5,0),"No Placeholder Yet") -> Rejected - Revise & Resubmit | S14: =IF(AND(O14<>"",P14<>"",R14="Approved"),100%, IF(AND(O14<>"",P14<>""),66.67%, IF(O14<>"",33.33%, 0))) -> 0.6667 | T14: JC | W14: On-Site Power Supply & Transmission | X14: 33kV Main Consumer Plant Switchgear | AB14: Pending
A15: 6105A | B15: K124 | C15: 6243 | D15: E | E15: DST | F15: 0003 | G15: 0 | H15: =A15&B15&"-"&C15&"-"&D15&E15&"-"&F15 -> 6105AK124-6243-EDST-0003 | I15: ="Q24050972"&"-"&"06"&"-"&C15&"-"&D15&"-"&E15&"-"&F15 -> Q24050972-06-6243-E-DST-0003 | K15: =VLOOKUP(C15,'PPE WBS Codes'!$E$3:$F$79,2,0) -> 220/33 kV Plant Main Substation | L15: On-Site Power Supply & Distribution - 33kV Indoor Switchgear | M15: Datasheet | N15: =K15&" - "&L15&" - "&M15 -> 220/33 kV Plant Main Substation - On-Site Power Supply & Distribution - 33kV Indoor Switchgear - Datasheet | O15: 45959 | P15: 46153 | Q15: =IFERROR(VLOOKUP(PPE_PH1_CDDL[[#This Row],[RDMC Document Number]],[3]Docs!$B:$F,4,0),"No Placeholder Yet") -> IFU - Issued for Use | R15: =IFERROR(VLOOKUP(PPE_PH1_CDDL[[#This Row],[RDMC Document Number]],[3]Docs!$B:$F,5,0),"No Placeholder Yet") -> Rejected - Revise & Resubmit | S15: =IF(AND(O15<>"",P15<>"",R15="Approved"),100%, IF(AND(O15<>"",P15<>""),66.67%, IF(O15<>"",33.33%, 0))) -> 0.6667 | T15: JC | W15: On-Site Power Supply & Distribution | X15: 33kV Indoor Switchgear | AB15: Pending
A16: 6105A | B16: K124 | C16: 6243 | D16: E | E16: DST | F16: 0004 | G16: A | H16: =A16&B16&"-"&C16&"-"&D16&E16&"-"&F16 -> 6105AK124-6243-EDST-0004 | I16: ="Q24050972"&"-"&"06"&"-"&C16&"-"&D16&"-"&E16&"-"&F16 -> Q24050972-06-6243-E-DST-0004 | K16: =VLOOKUP(C16,'PPE WBS Codes'!$E$3:$F$79,2,0) -> 220/33 kV Plant Main Substation | L16: 33kV Distribution Switch Rooms - 4 x Battery Tripping Units (110V DC) | M16: Datasheet | N16: =K16&" - "&L16&" - "&M16 -> 220/33 kV Plant Main Substation - 33kV Distribution Switch Rooms - 4 x Battery Tripping Units (110V DC) - Datasheet | Q16: =IFERROR(VLOOKUP(PPE_PH1_CDDL[[#This Row],[RDMC Document Number]],[3]Docs!$B:$F,4,0),"No Placeholder Yet") -> RES - Reserved Placeholder | R16: =IFERROR(VLOOKUP(PPE_PH1_CDDL[[#This Row],[RDMC Document Number]],[3]Docs!$B:$F,5,0),"No Placeholder Yet") -> Pending | S16: =IF(AND(O16<>"",P16<>"",R16="Approved"),100%, IF(AND(O16<>"",P16<>""),66.67%, IF(O16<>"",33.33%, 0))) -> 0 | T16: JC | V16: TENDER | W16: Battery Tripping Units | X16: Datasheet | AB16: Pending
A17: 6105A | B17: K124 | C17: 6243 | D17: E | E17: DST | F17: 0005 | G17: A | H17: =A17&B17&"-"&C17&"-"&D17&E17&"-"&F17 -> 6105AK124-6243-EDST-0005 | I17: ="Q24050972"&"-"&"06"&"-"&C17&"-"&D17&"-"&E17&"-"&F17 -> Q24050972-06-6243-E-DST-0005 | K17: =VLOOKUP(C17,'PPE WBS Codes'!$E$3:$F$79,2,0) -> 220/33 kV Plant Main Substation | L17: Specification for 300mm², 33kV, Single-Core, Unarmored Aluminium Cable | M17: Datasheet | N17: =K17&" - "&L17&" - "&M17 -> 220/33 kV Plant Main Substation - Specification for 300mm², 33kV, Single-Core, Unarmored Aluminium Cable - Datasheet | Q17: =IFERROR(VLOOKUP(PPE_PH1_CDDL[[#This Row],[RDMC Document Number]],[3]Docs!$B:$F,4,0),"No Placeholder Yet") -> RES - Reserved Placeholder | R17: =IFERROR(VLOOKUP(PPE_PH1_CDDL[[#This Row],[RDMC Document Number]],[3]Docs!$B:$F,5,0),"No Placeholder Yet") -> Pending | S17: =IF(AND(O17<>"",P17<>"",R17="Approved"),100%, IF(AND(O17<>"",P17<>""),66.67%, IF(O17<>"",33.33%, 0))) -> 0 | T17: JC | V17: TENDER | W17: Specification for 300mm² | X17: 33kV, Single-Core, Unarmored Aluminium Cable | AB17: Pending
A18: 6105A | B18: K124 | C18: 6250 | D18: E | E18: DST | F18: 0001 | G18: A | H18: =A18&B18&"-"&C18&"-"&D18&E18&"-"&F18 -> 6105AK124-6250-EDST-0001 | I18: ="Q24050972"&"-"&"07"&"-"&C18&"-"&D18&"-"&E18&"-"&F18 -> Q24050972-07-6250-E-DST-0001 | K18: =VLOOKUP(C18,'PPE WBS Codes'!$E$3:$F$79,2,0) -> Power Conditioning Equipment | L18: Synchronous Condenser and Excitation System | M18: Datasheet | N18: =K18&" - "&L18&" - "&M18 -> Power Conditioning Equipment - Synchronous Condenser and Excitation System - Datasheet | Q18: =IFERROR(VLOOKUP(PPE_PH1_CDDL[[#This Row],[RDMC Document Number]],[3]Docs!$B:$F,4,0),"No Placeholder Yet") -> RES - Reserved Placeholder | R18: =IFERROR(VLOOKUP(PPE_PH1_CDDL[[#This Row],[RDMC Document Number]],[3]Docs!$B:$F,5,0),"No Placeholder Yet") -> Pending | S18: =IF(AND(O18<>"",P18<>"",R18="Approved"),100%, IF(AND(O18<>"",P18<>""),66.67%, IF(O18<>"",33.33%, 0))) -> 0 | T18: ET | V18: TENDER | W18: Synchronous Condenser | X18: Datasheet | AB18: Pending
A19: 6105A | B19: K124 | C19: 6260 | D19: E | E19: DST | F19: 0008 | G19: 2 | H19: =A19&B19&"-"&C19&"-"&D19&E19&"-"&F19 -> 6105AK124-6260-EDST-0008 | I19: ="Q24050972"&"-"&"04"&"-"&C19&"-"&D19&"-"&E19&"-"&F19 -> Q24050972-04-6260-E-DST-0008 | K19: =VLOOKUP(C19,'PPE WBS Codes'!$E$3:$F$79,2,0) -> Emergency Power Generation (Main Plant) | L19: Neutral Earthing Compensator Resistor (33kV NECr) | M19: Datasheet | N19: =K19&" - "&L19&" - "&M19 -> Emergency Power Generation (Main Plant) - Neutral Earthing Compensator Resistor (33kV NECr) - Datasheet | O19: 45954 | P19: 46162 | Q19: =IFERROR(VLOOKUP(PPE_PH1_CDDL[[#This Row],[RDMC Document Number]],[3]Docs!$B:$F,4,0),"No Placeholder Yet") -> IFU - Issued for Use | R19: =IFERROR(VLOOKUP(PPE_PH1_CDDL[[#This Row],[RDMC Document Number]],[3]Docs!$B:$F,5,0),"No Placeholder Yet") -> Pending | S19: =IF(AND(O19<>"",P19<>"",R19="Approved"),100%, IF(AND(O19<>"",P19<>""),66.67%, IF(O19<>"",33.33%, 0))) -> 0.6667 | T19: IS | W19: Neutral Earthing Compensator Resistor (33kV NECr) | X19: Datasheet | AB19: Pending
A20: 6105A | B20: K124 | C20: 6260 | D20: E | E20: DST | F20: 0016 | G20: A | H20: =A20&B20&"-"&C20&"-"&D20&E20&"-"&F20 -> 6105AK124-6260-EDST-0016 | I20: ="Q24050972"&"-"&"07"&"-"&C20&"-"&D20&"-"&E20&"-"&F20 -> Q24050972-07-6260-E-DST-0016 | K20: =VLOOKUP(C20,'PPE WBS Codes'!$E$3:$F$79,2,0) -> Emergency Power Generation (Main Plant) | L20: 630kVA Mini-substation (11/0.4kV) | M20: Datasheet | N20: =K20&" - "&L20&" - "&M20 -> Emergency Power Generation (Main Plant) - 630kVA Mini-substation (11/0.4kV) - Datasheet | Q20: =IFERROR(VLOOKUP(PPE_PH1_CDDL[[#This Row],[RDMC Document Number]],[3]Docs!$B:$F,4,0),"No Placeholder Yet") -> RES - Reserved Placeholder | R20: =IFERROR(VLOOKUP(PPE_PH1_CDDL[[#This Row],[RDMC Document Number]],[3]Docs!$B:$F,5,0),"No Placeholder Yet") -> Pending | S20: =IF(AND(O20<>"",P20<>"",R20="Approved"),100%, IF(AND(O20<>"",P20<>""),66.67%, IF(O20<>"",33.33%, 0))) -> 0 | T20: IS | V20: TENDER | W20: Substation | X20: Datasheet | AB20: Pending
A21: 6105A | B21: K124 | C21: 6262 | D21: E | E21: DST | F21: 0004 | G21: A | H21: =A21&B21&"-"&C21&"-"&D21&E21&"-"&F21 -> 6105AK124-6262-EDST-0004 | I21: ="Q24050972"&"-"&"08"&"-"&C21&"-"&D21&"-"&E21&"-"&F21 -> Q24050972-08-6262-E-DST-0004 | J21: Sht 1 of 1 | K21: Emergency Power Generation | L21: 11kVA MV E-house type 1B | M21: Internal Views | N21: =K21&" - "&L21&" - "&M21&" - "&J21 -> Emergency Power Generation - 11kVA MV E-house type 1B - Internal Views - Sht 1 of 1 | Q21: =IFERROR(VLOOKUP(PPE_PH1_CDDL[[#This Row],[RDMC Document Number]],[3]Docs!$B:$F,4,0),"No Placeholder Yet") -> RES - Reserved Placeholder | R21: =IFERROR(VLOOKUP(PPE_PH1_CDDL[[#This Row],[RDMC Document Number]],[3]Docs!$B:$F,5,0),"No Placeholder Yet") -> Pending | S21: =IF(AND(O21<>"",P21<>"",R21="Approved"),100%, IF(AND(O21<>"",P21<>""),66.67%, IF(O21<>"",33.33%, 0))) -> 0 | T21: IS | V21: TENDER | W21: 11kVA MV E-house type 1B | X21: MV Control Room | AB21: Pending
A22: 6105A | B22: K124 | C22: 6262 | D22: E | E22: DST | F22: 0001 | G22: A | H22: =A22&B22&"-"&C22&"-"&D22&E22&"-"&F22 -> 6105AK124-6262-EDST-0001 | I22: ="Q24050972"&"-"&"07"&"-"&C22&"-"&D22&"-"&E22&"-"&F22 -> Q24050972-07-6262-E-DST-0001 | K22: =VLOOKUP(C22,'PPE WBS Codes'!$E$3:$F$79,2,0) -> Emergency Power Substation 1 and Control Room 1 | L22: Auxiliary 400V AC Panel | M22: Datasheet | N22: =K22&" - "&L22&" - "&M22 -> Emergency Power Substation 1 and Control Room 1 - Auxiliary 400V AC Panel - Datasheet | Q22: =IFERROR(VLOOKUP(PPE_PH1_CDDL[[#This Row],[RDMC Document Number]],[3]Docs!$B:$F,4,0),"No Placeholder Yet") -> RES - Reserved Placeholder | R22: =IFERROR(VLOOKUP(PPE_PH1_CDDL[[#This Row],[RDMC Document Number]],[3]Docs!$B:$F,5,0),"No Placeholder Yet") -> Pending | S22: =IF(AND(O22<>"",P22<>"",R22="Approved"),100%, IF(AND(O22<>"",P22<>""),66.67%, IF(O22<>"",33.33%, 0))) -> 0 | T22: IS | V22: TENDER | W22: Auxiliary 400V AC Panel | X22: Datasheet | AB22: Pending
A23: 6105A | B23: K124 | C23: 6262 | D23: E | E23: DST | F23: 0002 | G23: 0 | H23: =A23&B23&"-"&C23&"-"&D23&E23&"-"&F23 -> 6105AK124-6262-EDST-0002 | I23: ="Q24050972"&"-"&"07"&"-"&C23&"-"&D23&"-"&E23&"-"&F23 -> Q24050972-07-6262-E-DST-0002 | K23: =VLOOKUP(C23,'PPE WBS Codes'!$E$3:$F$79,2,0) -> Emergency Power Substation 1 and Control Room 1 | L23: Auxiliary 230V AC Battery Back-up Supply | M23: Datasheet | N23: =K23&" - "&L23&" - "&M23 -> Emergency Power Substation 1 and Control Room 1 - Auxiliary 230V AC Battery Back-up Supply - Datasheet | O23: 45956 | P23: 45968 | Q23: =IFERROR(VLOOKUP(PPE_PH1_CDDL[[#This Row],[RDMC Document Number]],[3]Docs!$B:$F,4,0),"No Placeholder Yet") -> IFD - Issued for Design | R23: =IFERROR(VLOOKUP(PPE_PH1_CDDL[[#This Row],[RDMC Document Number]],[3]Docs!$B:$F,5,0),"No Placeholder Yet") -> Approved | S23: =IF(AND(O23<>"",P23<>"",R23="Approved"),100%, IF(AND(O23<>"",P23<>""),66.67%, IF(O23<>"",33.33%, 0))) -> 1 | T23: IS | U23: Approved | W23: Auxiliary 230V AC Battery Back-up Supply | X23: Datasheet | AB23: Pending
A24: 6105A | B24: K124 | C24: 6262 | D24: E | E24: DST | F24: 0003 | G24: 1 | H24: =A24&B24&"-"&C24&"-"&D24&E24&"-"&F24 -> 6105AK124-6262-EDST-0003 | I24: ="Q24050972"&"-"&"07"&"-"&C24&"-"&D24&"-"&E24&"-"&F24 -> Q24050972-07-6262-E-DST-0003 | K24: =VLOOKUP(C24,'PPE WBS Codes'!$E$3:$F$79,2,0) -> Emergency Power Substation 1 and Control Room 1 | L24: 11kV MV Switchgear | M24: Datasheet | N24: =K24&" - "&L24&" - "&M24 -> Emergency Power Substation 1 and Control Room 1 - 11kV MV Switchgear - Datasheet | O24: 45952 | P24: 45994 | Q24: =IFERROR(VLOOKUP(PPE_PH1_CDDL[[#This Row],[RDMC Document Number]],[3]Docs!$B:$F,4,0),"No Placeholder Yet") -> IFU - Issued for Use | R24: =IFERROR(VLOOKUP(PPE_PH1_CDDL[[#This Row],[RDMC Document Number]],[3]Docs!$B:$F,5,0),"No Placeholder Yet") -> Approved | S24: =IF(AND(O24<>"",P24<>"",R24="Approved"),100%, IF(AND(O24<>"",P24<>""),66.67%, IF(O24<>"",33.33%, 0))) -> 1 | T24: IS | U24: Approved | W24: 11kV MV Switchgear | X24: Datasheet | AB24: Pending
A25: 6105A | B25: K124 | C25: 6263 | D25: E | E25: DST | F25: 0002 | G25: A | H25: =A25&B25&"-"&C25&"-"&D25&E25&"-"&F25 -> 6105AK124-6263-EDST-0002 | I25: ="Q24050972"&"-"&"07"&"-"&C25&"-"&D25&"-"&E25&"-"&F25 -> Q24050972-07-6263-E-DST-0002 | K25: =VLOOKUP(C25,'PPE WBS Codes'!$E$3:$F$79,2,0) -> 36 MVA Power Station 1 | L25: 20 MW 11kV Load Banks | M25: Datasheet | N25: =K25&" - "&L25&" - "&M25 -> 36 MVA Power Station 1 - 20 MW 11kV Load Banks - Datasheet | Q25: =IFERROR(VLOOKUP(PPE_PH1_CDDL[[#This Row],[RDMC Document Number]],[3]Docs!$B:$F,4,0),"No Placeholder Yet") -> RES - Reserved Placeholder | R25: =IFERROR(VLOOKUP(PPE_PH1_CDDL[[#This Row],[RDMC Document Number]],[3]Docs!$B:$F,5,0),"No Placeholder Yet") -> Pending | S25: =IF(AND(O25<>"",P25<>"",R25="Approved"),100%, IF(AND(O25<>"",P25<>""),66.67%, IF(O25<>"",33.33%, 0))) -> 0 | T25: JC | V25: TENDER | W25: 20 MW 11kV Load banks | X25: Datasheet | AB25: Pending
A26: 6105A | B26: K124 | C26: 6263 | D26: E | E26: DST | F26: 0003 | G26: 0 | H26: =A26&B26&"-"&C26&"-"&D26&E26&"-"&F26 -> 6105AK124-6263-EDST-0003 | I26: ="Q24050972"&"-"&"07"&"-"&C26&"-"&D26&"-"&E26&"-"&F26 -> Q24050972-07-6263-E-DST-0003 | K26: =VLOOKUP(C26,'PPE WBS Codes'!$E$3:$F$79,2,0) -> 36 MVA Power Station 1 | L26: High Speed Diesel Generators | M26: Datasheet | N26: =K26&" - "&L26&" - "&M26 -> 36 MVA Power Station 1 - High Speed Diesel Generators - Datasheet | O26: 45956 | P26: 45979 | Q26: =IFERROR(VLOOKUP(PPE_PH1_CDDL[[#This Row],[RDMC Document Number]],[3]Docs!$B:$F,4,0),"No Placeholder Yet") -> IFD - Issued for Design | R26: =IFERROR(VLOOKUP(PPE_PH1_CDDL[[#This Row],[RDMC Document Number]],[3]Docs!$B:$F,5,0),"No Placeholder Yet") -> Pending | S26: =IF(AND(O26<>"",P26<>"",R26="Approved"),100%, IF(AND(O26<>"",P26<>""),66.67%, IF(O26<>"",33.33%, 0))) -> 0.6667 | T26: IS | W26: High Speed Diesel Generators | X26: Datasheet | AB26: Pending
A27: 6105A | B27: K124 | C27: 6263 | D27: E | E27: DST | F27: 0004 | G27: 0 | H27: =A27&B27&"-"&C27&"-"&D27&E27&"-"&F27 -> 6105AK124-6263-EDST-0004 | I27: ="Q24050972"&"-"&"07"&"-"&C27&"-"&D27&"-"&E27&"-"&F27 -> Q24050972-07-6263-E-DST-0004 | K27: =VLOOKUP(C27,'PPE WBS Codes'!$E$3:$F$79,2,0) -> 36 MVA Power Station 1 | L27: Neutral Earthing Resistor (11kV NER) | M27: Datasheet | N27: =K27&" - "&L27&" - "&M27 -> 36 MVA Power Station 1 - Neutral Earthing Resistor (11kV NER) - Datasheet | O27: 45956 | P27: 45968 | Q27: =IFERROR(VLOOKUP(PPE_PH1_CDDL[[#This Row],[RDMC Document Number]],[3]Docs!$B:$F,4,0),"No Placeholder Yet") -> IFD - Issued for Design | R27: =IFERROR(VLOOKUP(PPE_PH1_CDDL[[#This Row],[RDMC Document Number]],[3]Docs!$B:$F,5,0),"No Placeholder Yet") -> Approved | S27: =IF(AND(O27<>"",P27<>"",R27="Approved"),100%, IF(AND(O27<>"",P27<>""),66.67%, IF(O27<>"",33.33%, 0))) -> 1 | T27: IS | U27: Approved | W27: Neutral Earthing Resistor (11kV NER) | X27: Datasheet | AB27: Pending
A28: 6105A | B28: K124 | C28: 6263 | D28: E | E28: DST | F28: 0005 | G28: A | H28: =A28&B28&"-"&C28&"-"&D28&E28&"-"&F28 -> 6105AK124-6263-EDST-0005 | I28: ="Q24050972"&"-"&"07"&"-"&C28&"-"&D28&"-"&E28&"-"&F28 -> Q24050972-07-6263-E-DST-0005 | K28: =VLOOKUP(C28,'PPE WBS Codes'!$E$3:$F$79,2,0) -> 36 MVA Power Station 1 | L28: 11kV RMU for Load Banks | M28: Datasheet | N28: =K28&" - "&L28&" - "&M28 -> 36 MVA Power Station 1 - 11kV RMU for Load Banks - Datasheet | Q28: =IFERROR(VLOOKUP(PPE_PH1_CDDL[[#This Row],[RDMC Document Number]],[3]Docs!$B:$F,4,0),"No Placeholder Yet") -> RES - Reserved Placeholder | R28: =IFERROR(VLOOKUP(PPE_PH1_CDDL[[#This Row],[RDMC Document Number]],[3]Docs!$B:$F,5,0),"No Placeholder Yet") -> Pending | S28: =IF(AND(O28<>"",P28<>"",R28="Approved"),100%, IF(AND(O28<>"",P28<>""),66.67%, IF(O28<>"",33.33%, 0))) -> 0 | T28: JC | V28: TENDER | W28: 11kV RMU for Load Banks | X28: Datasheet | AB28: Pending
A29: 6105A | B29: K124 | C29: 6264 | D29: E | E29: DST | F29: 0001 | G29: A | H29: =A29&B29&"-"&C29&"-"&D29&E29&"-"&F29 -> 6105AK124-6264-EDST-0001 | I29: ="Q24050972"&"-"&"08"&"-"&C29&"-"&D29&"-"&E29&"-"&F29 -> Q24050972-08-6264-E-DST-0001 | K29: =VLOOKUP(C29,'PPE WBS Codes'!$E$3:$F$79,2,0) -> Bulk Diesel Storage 1 | L29: Bulk Fuel Tanks | M29: Datasheet | N29: =K29&" - "&L29&" - "&M29 -> Bulk Diesel Storage 1 - Bulk Fuel Tanks - Datasheet | Q29: =IFERROR(VLOOKUP(PPE_PH1_CDDL[[#This Row],[RDMC Document Number]],[3]Docs!$B:$F,4,0),"No Placeholder Yet") -> RES - Reserved Placeholder | R29: =IFERROR(VLOOKUP(PPE_PH1_CDDL[[#This Row],[RDMC Document Number]],[3]Docs!$B:$F,5,0),"No Placeholder Yet") -> Pending | S29: =IF(AND(O29<>"",P29<>"",R29="Approved"),100%, IF(AND(O29<>"",P29<>""),66.67%, IF(O29<>"",33.33%, 0))) -> 0 | T29: IS | V29: TENDER | W29: Bulk Fuel Tanks | X29: Datasheet | AB29: Pending
A30: 6105A | B30: K124 | C30: 6286 | D30: E | E30: DST | F30: 0001 | G30: 0 | H30: =A30&B30&"-"&C30&"-"&D30&E30&"-"&F30 -> 6105AK124-6286-EDST-0001 | I30: ="Q24050972"&"-"&"06"&"-"&C30&"-"&D30&"-"&E30&"-"&F30 -> Q24050972-06-6286-E-DST-0001 | K30: =VLOOKUP(C30,'PPE WBS Codes'!$E$3:$F$79,2,0) -> Primary Crushing | L30: On-Site Power Supply & Transmission_ MV 33kV Mining Sub MV Switchgear | M30: Datasheet | N30: =K30&" - "&L30&" - "&M30 -> Primary Crushing - On-Site Power Supply & Transmission_ MV 33kV Mining Sub MV Switchgear - Datasheet | O30: 45952 | P30: 45968 | Q30: =IFERROR(VLOOKUP(PPE_PH1_CDDL[[#This Row],[RDMC Document Number]],[3]Docs!$B:$F,4,0),"No Placeholder Yet") -> IFD - Issued for Design | R30: =IFERROR(VLOOKUP(PPE_PH1_CDDL[[#This Row],[RDMC Document Number]],[3]Docs!$B:$F,5,0),"No Placeholder Yet") -> Approved | S30: =IF(AND(O30<>"",P30<>"",R30="Approved"),100%, IF(AND(O30<>"",P30<>""),66.67%, IF(O30<>"",33.33%, 0))) -> 1 | T30: JC | U30: Approved | W30: On-Site Power Supply & Transmission | X30: MV 33kV Mining Sub MV Switchgear | AB30: Pending
A31: 6105A | B31: K124 | C31: 6286 | D31: E | E31: DST | F31: 0002 | G31: A | H31: =A31&B31&"-"&C31&"-"&D31&E31&"-"&F31 -> 6105AK124-6286-EDST-0002 | I31: ="Q24050972"&"-"&"07"&"-"&C31&"-"&D31&"-"&E31&"-"&F31 -> Q24050972-07-6286-E-DST-0002 | K31: =VLOOKUP(C31,'PPE WBS Codes'!$E$3:$F$79,2,0) -> Primary Crushing | L31: 11kV Substation | M31: Datasheet | N31: =K31&" - "&L31&" - "&M31 -> Primary Crushing - 11kV Substation - Datasheet | Q31: =IFERROR(VLOOKUP(PPE_PH1_CDDL[[#This Row],[RDMC Document Number]],[3]Docs!$B:$F,4,0),"No Placeholder Yet") -> RES - Reserved Placeholder | R31: =IFERROR(VLOOKUP(PPE_PH1_CDDL[[#This Row],[RDMC Document Number]],[3]Docs!$B:$F,5,0),"No Placeholder Yet") -> Pending | S31: =IF(AND(O31<>"",P31<>"",R31="Approved"),100%, IF(AND(O31<>"",P31<>""),66.67%, IF(O31<>"",33.33%, 0))) -> 0 | T31: JC | V31: TENDER | W31: 11kV Substation | X31: Datasheet | AB31: Pending
A32: 6105A | B32: K124 | C32: 6286 | D32: E | E32: DST | F32: 0003 | G32: A | H32: =A32&B32&"-"&C32&"-"&D32&E32&"-"&F32 -> 6105AK124-6286-EDST-0003 | I32: ="Q24050972"&"-"&"07"&"-"&C32&"-"&D32&"-"&E32&"-"&F32 -> Q24050972-07-6286-E-DST-0003 | K32: =VLOOKUP(C32,'PPE WBS Codes'!$E$3:$F$79,2,0) -> Primary Crushing | L32: Auxiliary 400Vac Distribution Board | M32: Datasheet | N32: =K32&" - "&L32&" - "&M32 -> Primary Crushing - Auxiliary 400Vac Distribution Board - Datasheet | Q32: =IFERROR(VLOOKUP(PPE_PH1_CDDL[[#This Row],[RDMC Document Number]],[3]Docs!$B:$F,4,0),"No Placeholder Yet") -> RES - Reserved Placeholder | R32: =IFERROR(VLOOKUP(PPE_PH1_CDDL[[#This Row],[RDMC Document Number]],[3]Docs!$B:$F,5,0),"No Placeholder Yet") -> Pending | S32: =IF(AND(O32<>"",P32<>"",R32="Approved"),100%, IF(AND(O32<>"",P32<>""),66.67%, IF(O32<>"",33.33%, 0))) -> 0 | T32: IS | V32: TENDER | W32: Auxiliary 400Vac Distribution Board | X32: Datasheet | AB32: Pending
A33: 6105A | B33: K124 | C33: 6286 | D33: E | E33: DST | F33: 0004 | G33: 0 | H33: =A33&B33&"-"&C33&"-"&D33&E33&"-"&F33 -> 6105AK124-6286-EDST-0004 | I33: ="Q24050972"&"-"&"07"&"-"&C33&"-"&D33&"-"&E33&"-"&F33 -> Q24050972-07-6286-E-DST-0004 | K33: =VLOOKUP(C33,'PPE WBS Codes'!$E$3:$F$79,2,0) -> Primary Crushing | L33: 11kV Switchgear | M33: Datasheet | N33: =K33&" - "&L33&" - "&M33 -> Primary Crushing - 11kV Switchgear - Datasheet | O33: 45980 | P33: 45991 | Q33: =IFERROR(VLOOKUP(PPE_PH1_CDDL[[#This Row],[RDMC Document Number]],[3]Docs!$B:$F,4,0),"No Placeholder Yet") -> IFD - Issued for Design | R33: =IFERROR(VLOOKUP(PPE_PH1_CDDL[[#This Row],[RDMC Document Number]],[3]Docs!$B:$F,5,0),"No Placeholder Yet") -> Pending | S33: =IF(AND(O33<>"",P33<>"",R33="Approved"),100%, IF(AND(O33<>"",P33<>""),66.67%, IF(O33<>"",33.33%, 0))) -> 0.6667 | T33: IS | V33: TENDER | W33: 11KV Switchgear | X33: Datasheet | AB33: Pending
A34: 6105A | B34: K124 | C34: 6292 | D34: E | E34: DST | F34: 0001 | G34: A | H34: =A34&B34&"-"&C34&"-"&D34&E34&"-"&F34 -> 6105AK124-6292-EDST-0001 | I34: ="Q24050972"&"-"&"07"&"-"&C34&"-"&D34&"-"&E34&"-"&F34 -> Q24050972-07-6292-E-DST-0001 | K34: =VLOOKUP(C34,'PPE WBS Codes'!$E$3:$F$79,2,0) -> 11/33 kV Solar PV Substation 1 and Control Room 1 | L34: 33kV Indoor Switchgear | M34: Datasheet | N34: =K34&" - "&L34&" - "&M34 -> 11/33 kV Solar PV Substation 1 and Control Room 1 - 33kV Indoor Switchgear - Datasheet | Q34: =IFERROR(VLOOKUP(PPE_PH1_CDDL[[#This Row],[RDMC Document Number]],[3]Docs!$B:$F,4,0),"No Placeholder Yet") -> RES - Reserved Placeholder | R34: =IFERROR(VLOOKUP(PPE_PH1_CDDL[[#This Row],[RDMC Document Number]],[3]Docs!$B:$F,5,0),"No Placeholder Yet") -> Pending | S34: =IF(AND(O34<>"",P34<>"",R34="Approved"),100%, IF(AND(O34<>"",P34<>""),66.67%, IF(O34<>"",33.33%, 0))) -> 0 | T34: JC | V34: TENDER | W34: 33kV Indoor Switchgear | X34: Datasheet | AB34: Pending
A35: 6105A | B35: K124 | C35: 6292 | D35: E | E35: DST | F35: 0002 | G35: A | H35: =A35&B35&"-"&C35&"-"&D35&E35&"-"&F35 -> 6105AK124-6292-EDST-0002 | I35: ="Q24050972"&"-"&"07"&"-"&C35&"-"&D35&"-"&E35&"-"&F35 -> Q24050972-07-6292-E-DST-0002 | K35: =VLOOKUP(C35,'PPE WBS Codes'!$E$3:$F$79,2,0) -> 11/33 kV Solar PV Substation 1 and Control Room 1 | L35: 3x Battery Tripping Units 9110V DC | M35: Datasheet | N35: =K35&" - "&L35&" - "&M35 -> 11/33 kV Solar PV Substation 1 and Control Room 1 - 3x Battery Tripping Units 9110V DC - Datasheet | Q35: =IFERROR(VLOOKUP(PPE_PH1_CDDL[[#This Row],[RDMC Document Number]],[3]Docs!$B:$F,4,0),"No Placeholder Yet") -> RES - Reserved Placeholder | R35: =IFERROR(VLOOKUP(PPE_PH1_CDDL[[#This Row],[RDMC Document Number]],[3]Docs!$B:$F,5,0),"No Placeholder Yet") -> Pending | S35: =IF(AND(O35<>"",P35<>"",R35="Approved"),100%, IF(AND(O35<>"",P35<>""),66.67%, IF(O35<>"",33.33%, 0))) -> 0 | T35: JC | V35: TENDER | W35: 3x Battery Tripping Units 9110V DC | X35: Datasheet | AB35: Pending
A36: 6105A | B36: K124 | C36: 6292 | D36: E | E36: DST | F36: 0003 | G36: A | H36: =A36&B36&"-"&C36&"-"&D36&E36&"-"&F36 -> 6105AK124-6292-EDST-0003 | I36: ="Q24050972"&"-"&"07"&"-"&C36&"-"&D36&"-"&E36&"-"&F36 -> Q24050972-07-6292-E-DST-0003 | K36: =VLOOKUP(C36,'PPE WBS Codes'!$E$3:$F$79,2,0) -> 11/33 kV Solar PV Substation 1 and Control Room 1 | L36: MV 33kV Solar Plant Sub StationSwitchgear | M36: Datasheet | N36: =K36&" - "&L36&" - "&M36 -> 11/33 kV Solar PV Substation 1 and Control Room 1 - MV 33kV Solar Plant Sub StationSwitchgear - Datasheet | Q36: =IFERROR(VLOOKUP(PPE_PH1_CDDL[[#This Row],[RDMC Document Number]],[3]Docs!$B:$F,4,0),"No Placeholder Yet") -> RES - Reserved Placeholder | R36: =IFERROR(VLOOKUP(PPE_PH1_CDDL[[#This Row],[RDMC Document Number]],[3]Docs!$B:$F,5,0),"No Placeholder Yet") -> Pending | S36: =IF(AND(O36<>"",P36<>"",R36="Approved"),100%, IF(AND(O36<>"",P36<>""),66.67%, IF(O36<>"",33.33%, 0))) -> 0 | T36: JC | V36: TENDER | W36: MV 33kV Solar Plant | X36: Sub Station Switchgear | AB36: Pending
A37: 6105A | B37: K124 | C37: 6292 | D37: E | E37: DST | F37: 0004 | G37: A | H37: =A37&B37&"-"&C37&"-"&D37&E37&"-"&F37 -> 6105AK124-6292-EDST-0004 | I37: ="Q24050972"&"-"&"08"&"-"&C37&"-"&D37&"-"&E37&"-"&F37 -> Q24050972-08-6292-E-DST-0004 | K37: =VLOOKUP(C37,'PPE WBS Codes'!$E$3:$F$79,2,0) -> 11/33 kV Solar PV Substation 1 and Control Room 1 | L37: Primary Electrical Reticulation Network - Main Consumer Plant Reticulation | M37: Datasheet | N37: =K37&" - "&L37&" - "&M37 -> 11/33 kV Solar PV Substation 1 and Control Room 1 - Primary Electrical Reticulation Network - Main Consumer Plant Reticulation - Datasheet | Q37: =IFERROR(VLOOKUP(PPE_PH1_CDDL[[#This Row],[RDMC Document Number]],[3]Docs!$B:$F,4,0),"No Placeholder Yet") -> RES - Reserved Placeholder | R37: =IFERROR(VLOOKUP(PPE_PH1_CDDL[[#This Row],[RDMC Document Number]],[3]Docs!$B:$F,5,0),"No Placeholder Yet") -> Pending | S37: =IF(AND(O37<>"",P37<>"",R37="Approved"),100%, IF(AND(O37<>"",P37<>""),66.67%, IF(O37<>"",33.33%, 0))) -> 0 | T37: JC | V37: TENDER | W37: Primary Electrical Reticulation Network | X37: Main Consumer Plant Reticulation | AB37: Pending
A38: 6105A | B38: K124 | C38: 0100 | D38: E | E38: DST | F38: 0002 | G38: A | H38: =A38&B38&"-"&C38&"-"&D38&E38&"-"&F38 -> 6105AK124-0100-EDST-0002 | I38: ="Q24050972"&"-"&"07"&"-"&C38&"-"&D38&"-"&E38&"-"&F38 -> Q24050972-07-0100-E-DST-0002 | K38: =VLOOKUP(C38,'PPE WBS Codes'!$E$3:$F$79,2,0) -> Project Site Wide | L38: Pressurisation Fan - MV Switch Rooms | M38: Datasheet | N38: =K38&" - "&L38&" - "&M38 -> Project Site Wide - Pressurisation Fan - MV Switch Rooms - Datasheet | Q38: =IFERROR(VLOOKUP(PPE_PH1_CDDL[[#This Row],[RDMC Document Number]],[3]Docs!$B:$F,4,0),"No Placeholder Yet") -> RES - Reserved Placeholder | R38: =IFERROR(VLOOKUP(PPE_PH1_CDDL[[#This Row],[RDMC Document Number]],[3]Docs!$B:$F,5,0),"No Placeholder Yet") -> Pending | S38: =IF(AND(O38<>"",P38<>"",R38="Approved"),100%, IF(AND(O38<>"",P38<>""),66.67%, IF(O38<>"",33.33%, 0))) -> 0 | T38: IS | V38: TENDER | W38: Pressurisation Fan | X38: MV Switch Rooms | AB38: Pending
A39: 6105A | B39: K124 | C39: 0100 | D39: E | E39: DST | F39: 0003 | G39: A | H39: =A39&B39&"-"&C39&"-"&D39&E39&"-"&F39 -> 6105AK124-0100-EDST-0003 | I39: ="Q24050972"&"-"&"07"&"-"&C39&"-"&D39&"-"&E39&"-"&F39 -> Q24050972-07-0100-E-DST-0003 | K39: =VLOOKUP(C39,'PPE WBS Codes'!$E$3:$F$79,2,0) -> Project Site Wide | L39: Extraction Fan - MV Control Room | M39: Datasheet | N39: =K39&" - "&L39&" - "&M39 -> Project Site Wide - Extraction Fan - MV Control Room - Datasheet | Q39: =IFERROR(VLOOKUP(PPE_PH1_CDDL[[#This Row],[RDMC Document Number]],[3]Docs!$B:$F,4,0),"No Placeholder Yet") -> RES - Reserved Placeholder | R39: =IFERROR(VLOOKUP(PPE_PH1_CDDL[[#This Row],[RDMC Document Number]],[3]Docs!$B:$F,5,0),"No Placeholder Yet") -> Pending | S39: =IF(AND(O39<>"",P39<>"",R39="Approved"),100%, IF(AND(O39<>"",P39<>""),66.67%, IF(O39<>"",33.33%, 0))) -> 0 | T39: IS | V39: TENDER | W39: Extraction Fan | X39: MV Control Room | AB39: Pending
A40: 6105A | B40: K124 | C40: 6260 | D40: E | E40: DST | F40: 0017 | G40: A | H40: =A40&B40&"-"&C40&"-"&D40&E40&"-"&F40 -> 6105AK124-6260-EDST-0017 | I40: ="Q24050972"&"-"&"07"&"-"&C40&"-"&D40&"-"&E40&"-"&F40 -> Q24050972-07-6260-E-DST-0017 | J40: Sht 1 of 1 | K40: =VLOOKUP(C40,'PPE WBS Codes'!$E$3:$F$79,2,0) -> Emergency Power Generation (Main Plant) | L40: Bulk Fuel Storage 1 | M40: Datasheet | N40: =K40&" - "&L40&" - "&M40&" - "&J40 -> Emergency Power Generation (Main Plant) - Bulk Fuel Storage 1 - Datasheet - Sht 1 of 1 | Q40: =IFERROR(VLOOKUP(PPE_PH1_CDDL[[#This Row],[RDMC Document Number]],[3]Docs!$B:$F,4,0),"No Placeholder Yet") -> RES - Reserved Placeholder | R40: =IFERROR(VLOOKUP(PPE_PH1_CDDL[[#This Row],[RDMC Document Number]],[3]Docs!$B:$F,5,0),"No Placeholder Yet") -> Pending | S40: =IF(AND(O40<>"",P40<>"",R40="Approved"),100%, IF(AND(O40<>"",P40<>""),66.67%, IF(O40<>"",33.33%, 0))) -> 0 | T40: IS | V40: TENDER | W40: Bulk Fuel Storage 1 | X40: Datasheet | AB40: Pending
...

Sheet PPE WBS Codes
A1: L1 | B1: L2 | C1: L3 | D1: L4 | E1: Code | F1: Reko Diq Copper - Gold Project Facility Name
A2: 0 | B2: 0 | C2: 0 | D2: 0 | E2: 0000 | F2: General | H2: =E2&" - "&F2 -> 0000 - General
A3: 0 | B3: 1 | C3: 0 | D3: 0 | E3: 0100 | F3: Project Site Wide | H3: =E3&" - "&F3 -> 0100 - Project Site Wide
A4: 5 | B4: 3 | C4: 5 | D4: 0 | E4: 5350 | F4: Process Water Dams | H4: =E4&" - "&F4 -> 5350 - Process Water Dams
A5: 5 | B5: 3 | C5: 6 | D5: 0 | E5: 5360 | F5: Raw Water Dams | H5: =E5&" - "&F5 -> 5360 - Raw Water Dams
A6: 5 | B6: 3 | C6: 7 | D6: 0 | E6: 5370 | F6: Turkey Nests | H6: =E6&" - "&F6 -> 5370 - Turkey Nests
A7: 5 | B7: 5 | C7: 3 | D7: 0 | E7: 5530 | F7: Village Sewage | H7: =E7&" - "&F7 -> 5530 - Village Sewage
A8: 5 | B8: 6 | C8: 3 | D8: 0 | E8: 5630 | F8: Potable Water Treatment | H8: =E8&" - "&F8 -> 5630 - Potable Water Treatment
A9: 6 | B9: 1 | C9: 8 | D9: 0 | E9: 6180 | F9: Village | H9: =E9&" - "&F9 -> 6180 - Village
A10: 6 | B10: 1 | C10: 8 | D10: 1 | E10: 6181 | F10: Accommodation | H10: =E10&" - "&F10 -> 6181 - Accommodation
A11: 6 | B11: 1 | C11: 8 | D11: 2 | E11: 6182 | F11: Mess Hall and Food Storage | H11: =E11&" - "&F11 -> 6182 - Mess Hall and Food Storage
A12: 6 | B12: 1 | C12: 8 | D12: 3 | E12: 6183 | F12: Leisure Amenities | H12: =E12&" - "&F12 -> 6183 - Leisure Amenities
A13: 6 | B13: 1 | C13: 8 | D13: 4 | E13: 6184 | F13: Laundry Facilities | H13: =E13&" - "&F13 -> 6184 - Laundry Facilities
A14: 6 | B14: 1 | C14: 8 | D14: 5 | E14: 6185 | F14: Potable Water and Water Treatment | H14: =E14&" - "&F14 -> 6185 - Potable Water and Water Treatment
A15: 6 | B15: 1 | C15: 8 | D15: 6 | E15: 6186 | F15: Firewater - Tank & Fire Fighting System | H15: =E15&" - "&F15 -> 6186 - Firewater - Tank & Fire Fighting System
... A20: 6 | B20: 2 | C20: 1 | D20: 0 | E20: 6210 | F20: Power Stations | H20: =E20&" - "&F20 -> 6210 - Power Stations
A21: 6 | B21: 2 | C21: 1 | D21: 2 | E21: 6212 | F21: Power Station 1 | H21: 6212 - Power Station 1
A22: 6 | B22: 2 | C22: 3 | D22: 0 | E22: 6230 | F22: High Voltage (220 kV) Transmission Lines | H22: 6230 - High Voltage (220 kV) Transmission Lines
A23: 6 | B23: 2 | C23: 4 | D23: 0 | E23: 6240 | F23: High Voltage Substations | H23: =E23&" - "&F23 -> 6240 - High Voltage Substations
A24: 6 | B24: 2 | C24: 4 | D24: 1 | E24: 6241 | F24: 33/220 kV Solar PV Substation | H24: =E24&" - "&F24 -> 6241 - 33/220 kV Solar PV Substation
A25: 6 | B25: 2 | C25: 4 | D25: 2 | E25: 6242 | F25: 33/220 kV Power Station Substation | H25: =E25&" - "&F25 -> 6242 - 33/220 kV Power Station Substation
A26: 6 | B26: 2 | C26: 4 | D26: 3 | E26: 6243 | F26: 220/33 kV Plant Main Substation | H26: =E26&" - "&F26 -> 6243 - 220/33 kV Plant Main Substation
A27: 6 | B27: 2 | C27: 5 | D27: 0 | E27: 6250 | F27: Power Conditioning Equipment | H27: =E27&" - "&F27 -> 6250 - Power Conditioning Equipment
A28: 6 | B28: 2 | C28: 5 | D28: 1 | E28: 6251 | F28: Load Bank | H28: =E28&" - "&F28 -> 6251 - Load Bank
A29: 6 | B29: 2 | C29: 5 | D29: 2 | E29: 6252 | F29: Harmonic Filters 1 | H29: =E29&" - "&F29 -> 6252 - Harmonic Filters 1
A30: 6 | B30: 2 | C30: 5 | D30: 3 | E30: 6253 | F30: Synchronous Condenser 1 | H30: =E30&" - "&F30 -> 6253 - Synchronous Condenser 1
A31: 6 | B31: 2 | C31: 5 | D31: 4 | E31: 6254 | F31: Battery Energy Storage System 1 | H31: =E31&" - "&F31 -> 6254 - Battery Energy Storage System 1
A32: 6 | B32: 2 | C32: 5 | D32: 5 | E32: 6255 | F32: Harmonic Filters 2 | H32: =E32&" - "&F32 -> 6255 - Harmonic Filters 2
A33: 6 | B33: 2 | C33: 5 | D33: 6 | E33: 6256 | F33: Synchronous Condenser 2 | H33: =E33&" - "&F33 -> 6256 - Synchronous Condenser 2
A34: 6 | B34: 2 | C34: 5 | D34: 7 | E34: 6257 | F34: Battery Energy Storage System 2 | H34: =E34&" - "&F34 -> 6257 - Battery Energy Storage System 2
... A79: 7 | B79: 3 | C79: 3 | D79: 7 | E79: 7337 | F79: Port Qasim PIBT Control Room | H79: =E79&" - "&F79 -> 7337 - Port Qasim PIBT Control Room

Sheet Rev10 RDMC WBS Areas
B1: Facility Level ID | E1: Facility Code | F1: Reko Diq Project Facility Name | G1: Engineering | H1: Procurement | I1: Contracts | J1: Construction Management
A2: L1 | B2: L2 | C2: L3 | D2: L4
A3: 0 | B3: 0 | C3: 0 | D3: 0 | E3: 0 | F3: General | G3: - | H3: - | I3: - | J3: -
A4: 0 | B4: 1 | C4: 0 | D4: 0 | E4: 100 | F4: Project Site Wide | G4: - | H4: - | I4: - | J4: -
A5: 1 | B5: 0 | C5: 0 | D5: 0 | E5: 1000 | F5: Mining - OP | G5: RDMC/Fluor | H5: RDMC/Fluor | I5: RDMC/Fluor | J5: RDMC/Fluor
A6: 1 | B6: 1 | C6: 0 | D6: 0 | E6: 1100 | F6: Open Pit Mine | G6: RDMC/Fluo r | H6: RDMC/Fluo r | I6: RDMC/Fluo r | J6: RDMC/Fluo r
A7: 1 | B7: 1 | C7: 1 | D7: 0 | E7: 1110 | F7: Open Pit Mine Development | G7: RDMC | H7: RDMC | I7: RDMC | J7: RDMC
A8: 1 | B8: 1 | C8: 1 | D8: 1 | E8: 1111 | F8: Pre-Stripping | G8: RDMC | H8: RDMC | I8: RDMC | J8: RDMC
A9: 1 | B9: 1 | C9: 1 | D9: 2 | E9: 1112 | F9: Stockpiling | G9: RDMC | H9: RDMC | I9: RDMC | J9: RDMC
A10: 1 | B10: 1 | C10: 1 | D10: 3 | E10: 1113 | F10: Waste Dumps | G10: RDMC | H10: RDMC | I10: RDMC | J10: RDMC
A11: 1 | B11: 1 | C11: 1 | D11: 4 | E11: 1114 | F11: Run-of-Mine Pad | G11: RDMC | H11: RDMC | I11: RDMC | J11: RDMC
A12: 1 | B12: 1 | C12: 1 | D12: 5 | E12: 1115 | F12: Clearing, Grubbing and Topsoil Stockpiling | G12: RDMC | H12: RDMC | I12: RDMC | J12: RDMC
A13: 1 | B13: 1 | C13: 1 | D13: 9 | E13: 1119 | F13: Common Facilities and Services | G13: RDMC | H13: RDMC | I13: RDMC | J13: RDMC
A14: 1 | B14: 1 | C14: 2 | D14: 0 | E14: 1120 | F14: Open Pit Mining Equipment | G14: RDMC | H14: RDMC | I14: RDMC | J14: RDMC
... A846: 7 | B846: 1 | C846: 7 | D846: 1 | E846: 7171 | F846: Off-Site Desalinated Water Pipeline | G846: Future | H846: Future | I846: Future | J846: Future
A847: 7 | B847: 1 | C847: 7 | D847: 4 | E847: 7174 | F847: Off-Site Water Bulk Storage
A848: 7 | B848: 1 | C848: 7 | D848: 5 | E848: 7175 | F848: Off-Site Hamun-i-Mashkel (HIM) Bore Field | G848: Future | H848: Future | I848: Future | J848: Future
A849: 7 | B849: 1 | C849: 7 | D849: 6 | E849: 7176 | F849: Off-Site Borehole Fieldwater Pipeline - Hamun-i-Mashkel (HIM) | G849: Future | H849: Future | I849: Future | J849: Future
A850: 7 | B850: 1 | C850: 7 | D850: 7 | E850: 7177 | F850: Off-Site Fan Sediments Bore Field | G850: Fluor | H850: Fluor | I850: Fluor | J850: Fluor
A851: 7 | B851: 1 | C851: 7 | D851: 8 | E851: 7178 | F851: Off-Site Borehole Fieldwater Pipeline - Fan Sediments Main Line | G851: Fluor | H851: Fluor | I851: Fluor | J851: Fluor
A852: 7 | B852: 1 | C852: 7 | D852: 9 | E852: 7179 | F852: Off-Site Borehole Fieldwater Pipeline - Fan Sediments Construction Line | G852: RDMC | H852: RDMC | I852: Fluor | J852: Fluor
A853: 7 | B853: 1 | C853: 8 | D853: 0 | E853: 7180 | F853: Off-Site Services/Utilities | G853: RDMC | H853: RDMC | I853: RDMC | J853: RDMC
A854: 7 | B854: 1 | C854: 8 | D854: 1 | E854: 7181 | F854: Off-Site Fresh Water Distribution | G854: RDMC | H854: RDMC | I854: RDMC | J854: RDMC
A855: 7 | B855: 1 | C855: 8 | D855: 2 | E855: 7182 | F855: Off-Site Potable Water Distribution | G855: RDMC | H855: RDMC | I855: RDMC | J855: RDMC
A856: 7 | B856: 1 | C856: 8 | D856: 3 | E856: 7183 | F856: Off-Site Acid Rock Drainage (ARD) Water Distribution
A857: 7 | B857: 1 | C857: 8 | D857: 4 | E857: 7184 | F857: Off-Site Fire Water Distribution | G857: RDMC | H857: RDMC | I857: RDMC | J857: RDMC
A858: 7 | B858: 1 | C858: 8 | D858: 5 | E858: 7185 | F858: Off-Site Environmental Monitoring | G858: RDMC | H858: RDMC | I858: RDMC | J858: RDMC
A859: 7 | B859: 1 | C859: 8 | D859: 6 | E859: 7186 | F859: Off-Site Communications | G859: RDMC | H859: RDMC | I859: RDMC | J859: RDMC
A860: 7 | B860: 1 | C860: 8 | D860: 7 | E860: 7187 | F860: Off-Site Effluent Utilities | G860: RDMC | H860: RDMC | I860: RDMC | J860: RDMC
A861: 7 | B861: 1 | C861: 8 | D861: 8 | E861: 7188 | F861: Off-Site Other Utilities (Compressed Air & Propane, etc.) | G861: RDMC | H861: RDMC | I861: RDMC | J861: RDMC
A862: 7 | B862: 1 | C862: 9 | D862: 0 | E862: 7190 | F862: Off-Site Power Supply & Transmission
A863: 7 | B863: 1 | C863: 9 | D863: 1 | E863: 7191 | F863: Switchyard
A864: 7 | B864: 1 | C864: 9 | D864: 2 | E864: 7192 | F864: Off-Site Transmission
A865: 7 | B865: 1 | C865: 9 | D865: 3 | E865: 7193 | F865: Main Substation
A866: 7 | B866: 1 | C866: 9 | D866: 4 | E866: 7194 | F866: Power Generation
A867: 7 | B867: 1 | C867: 9 | D867: 9 | E867: 7199 | F867: Off-Site Power Facilities & Services
A868: 7 | B868: 2 | C868: 0 | D868: 0 | E868: 7200 | F868: Off-Site Port (Qasim & Gwadar) - (Not in Scope) | G868: - | H868: - | I868: - | J868: -
A869: 7 | B869: 2 | C869: 1 | D869: 0 | E869: 7210 | F869: Port Concentrate Handling | G869: - | H869: - | I869: - | J869: -
A870: 7 | B870: 2 | C870: 1 | D870: 1 | E870: 7211 | F870: Port Copper Concentrate Thickening | G870: - | H870: - | I870: - | J870: -
A871: 7 | B871: 2 | C871: 1 | D871: 2 | E871: 7212 | F871: Port Concentrate Filtration | G871: - | H871: - | I871: - | J871: -
...

Sheet Discipline Codes
A1: DISCIPLINE CODES
A4: Code | B4: Discipline/Function Identifier
A5: A | B5: Architectural | E5: Pending
A6: B | B6: Project Controls | E6: Updated
A7: C | B7: Civil/Concrete
A8: D | B8: Supply Chain
A9: E | B9: Electrical
A10: F | B10: Process
A11: G | B11: General
A12: H | B12: Health & Safety / Security
A13: I | B13: Instrumentation
A14: J | B14: Environmental / Social Impact
A15: L | B15: Human Resources
A16: M | B16: Mechanical
A17: N | B17: Mining
A18: P | B18: Piping
... A23: W | B23: Earthworks / Drainage / Fencing / Roads / Water

Sheet Document and Drawing Type
A1: Document and Drawing Types
A3: Code | B3: Document Type identifier | C3: Description
A4: GENERAL
A5: AUT | B5: Authority | C5: - Permitting - Authority Implementation Plan - Authority Approval Packages - Regulatory Compliance - Environmental Permitting Compliance Requirements | E5: AUT
A6: BLT | B6: Battery Limit | C6: - Battery Limit Table | E6: BLT
A7: BOE | B7: Basis of Estimate | E7: BOE
A8: BOS | B8: Basis of Schedule | E8: BOS
A9: BOM | B9: Bill of Material | E9: BOM
A10: CAL | B10: Calculation | E10: CAL
A11: CHR | B11: Chart | C11: Organization Chart, Department Chart | E11: CHR
A12: CON | B12: Contract | C12: Any contract documentation | E12: CON
A13: DBD | B13: Design Basis and Criteria | C13: Design Criteria of the Project | E13: DBD
A14: DBK | B14: Project Data Book | C14: - Manufacturer Data Records | E14: DBK
A15: DDR | B15: Document and Data Register | C15: Master Data and Document Register for Supplier, Sub-Contractors | E15: DDR
A16: DEM | B16: Demolition | C16: Demolition Documents | E16: DEM
A17: DST | B17: Datasheet | E17: DST
A18: DTA | B18: Data (Digital Record) | C18: Any data e.g. Survey Data | E18: DTA
A19: EQL | B19: Equipment List | C19: Specific list for equipments | E19: EQL
A20: EST | B20: Estimates | E20: EST
A21: EXE | B21: Execution | C21: Can be used for Supplier Data - if not specify on the list | E21: EXE
A22: FRM | B22: Forms | E22: FRM
A23: GDL | B23: Guideline | C23: - Guideline - Protocols | E23: GDL
A24: HAC | B24: Hazard Classification | C24: HAZOP, Hazard Analysis, Hazard identification | E24: HAC
A25: HMB | B25: Heat Material Balance | E25: HMB
A26: IDX | B26: Index | C26: Technical and Non-technical | E26: IDX
A27: INS | B27: Instructions | C27: e.g. operation instructions, installation instructions | E27: INS
A28: IOM | B28: Installation Operation and Maintenance Manual | E28: IOM
A29: ITP | B29: Inspection Test Plan | E29: ITP
A30: IWP | B30: Installation Work Package | E30: IWP
A31: LST | B31: List/Matrix | C31: Technical List: Valve List, Motor List, Instrument List, Spare Part List Non-Technical List: Distribution Matrix, Communication Matrix | E31: LST
A32: LTR | B32: Letter | E32: LTR
A33: MAN | B33: Manual | E33: MAN
A34: MDL | B34: Models | C34: - 3Models | E34: MDL
A35: MDR | B35: Master Document Register | C35: Document Register for Engineering - Documentation System Description - Document Filing Index - Transmittal Log - Gate Review Completed | E35: MDR
A36: MEM | B36: Memorandum | E36: MEM
A37: MOM | B37: Minutes of Meeting | E37: MOM
A38: MTO | B38: Material Take Off | E38: MTO
A39: NAR | B39: Narrative | C39: - Process Control Narrative - Safeguarding Narrative | E39: NAR
A40: NCR | B40: Non-Conformance Report | E40: NCR
A41: PCN | B41: Project Change Notice | E41: PCN
...
